Traceback (most recent call last):
  File "server.py", line 166, in <module>
    server(server_port=port)
  File "server.py", line 129, in server
    server_socket.bind(('', server_port))
OSError: [Errno 98] Address already in use
Exception in thread Thread-1:
Traceback (most recent call last):
  FileTraceback (most recent call last):
  File "server.py", line 166, in <module>
    server(server_port=port)
  File "server.py", line 134, in server
    message = utils.receive_message(connection_socket).decode('utf-8')
  File "/home/infinity/PycharmProjects/progres/exercice2/utils.py", line 26, in receive_message
    bl = receive_all(sock, header_struct.size)
  File "/home/infinity/PycharmProjects/progres/exercice2/utils.py", line 12, in receive_all
    raise EOFError("socket closed with %d bytes left "
EOFError: socket closed with %d bytes left in this block
with %d bytes left "
EOFError: socket closed with %d bytes left in this block
